<?xml version="1.0" encoding="utf-8"?>
<!-- from https://github.com/vikashplus/mj_envs/tree/master/mj_envs/hand_manipulation_suite/assets -->
<!-- Information about door can be found in this paper: https://arxiv.org/pdf/1709.10087.pdf -->

<mujoco model="particle">
  <asset>
    <texture file="../textures/light-wood.png" type="cube" name="light-wood" />
    <texture file="../textures/dark-wood.png" type="cube" name="dark-wood" />
    <texture file="../textures/brass-ambra.png" type="cube" name="metal" />
    <material name="MatMetal" texture="metal" specular="1" shininess="0.3" rgba="0.9 0.9 0.9 1" />
    <material name="MatDarkWood" texture="dark-wood" texrepeat="3 3" specular="0.4" shininess="0.1" />
    <material name="MatLightWood" texture="light-wood" texrepeat="3 3" specular="0.4" shininess="0.1" />
  </asset>

    <worldbody>
      <body>
        <body name="object">
          <site name="origin" pos="0 0 0" rgba="0 0 0 0" size="0.005"/>
          <body name="body" pos="0 0 0.015">          
            <geom pos="0.0 0.0 0.0" size="0.05 0.06 0.015" type="box" friction="1 1 1" group="0" name="body" material="MatLightWood"/>
            <geom pos="0 0.05 0.0" size="0.015 0.05 0.015" type="box" friction="1 1 1" group="0" name="handle" material="MatLightWood"/>
            <inertial pos="0. 0 0" mass="0.2"  diaginertia="0.0001 0.0001 0.0001" />

          <body name="nail" pos="0 0 0.015">
            <inertial pos="0. 0 0" mass="0.01"  diaginertia="0.0001 0.0001 0.0001" />
            <site name="nailing_point" pos="0 0 0" rgba="0 0 0 0" size="0.005"/>
            <geom size="0.002 0.015" pos="0 0 0.015" type="cylinder" rgba="1 1 1 1" group="0" material="MatMetal"/>
            <geom size="0.005 0.002" pos="0 0 0.032" type="cylinder" rgba="1 1 1 1" group="0" material="MatMetal"/>
            <joint name="joint_nail"
                  type="slide" axis="0 0 1"
                  limited="true" range="-0.3 0" frictionloss="1.0" damping="0.1" armature="0.1"
                  />
          </body>

          </body>
        </body>

        <site name="bottom_site" pos="0 0 -0.0207" rgba="0 0 0 0" size="0.005"/>
        <site name="top_site" pos="0 0 0.007" rgba="0 0 0 0" size="0.005"/>
        <site name="horizontal_radius_site" pos="0 0 0" rgba="0 0 0 0" size="0.003"/>
      </body>

    </worldbody>
</mujoco>