<?xml version="1.0" encoding="utf-8"?>
<!-- from https://github.com/vikashplus/mj_envs/tree/master/mj_envs/hand_manipulation_suite/assets -->
<!-- Information about door can be found in this paper: https://arxiv.org/pdf/1709.10087.pdf -->

<mujoco model="door_lock">
  <asset>
    <texture file="../textures/steel-brushed.png" type="cube" name="metal" />
    <texture file="../textures/navy.png" type="cube" name="glass" />
    <material name="MatBright" texture="metal" specular="1" shininess="0.3" rgba="0.5 0.5 0.5 1" />
    <material name="MatDark" texture="metal" specular="0.2" shininess="0.3" rgba="0.2 0.2 0.2 1" />
    <material name="MatGlass" texture="glass" specular="1" shininess="0.3" rgba="1.0 1.0 1.0 1" />
  </asset>
    <worldbody>
      <body>
        <body name="object">
          <body name="object" pos="0 0 1.0">
            <body name="frame" pos="0 0 0" quat="0.707107 0 0 -0.707107">
              <geom name="r_frame"
                size="0.05 1.0" pos="0.5 0 0" type="cylinder" rgba="1 1 1 1"
                contype="0" conaffinity="0"  group="1"
                />
              <geom name="l_frame"
                size="0.05 1.0" pos="-0.5 0 0" type="cylinder" rgba="1 1 1 1"
                contype="0" conaffinity="0"  group="1"
                />
              <body name="door" pos="0 0.1 0">
                <inertial pos="0 0 0" mass="1.47392" diaginertia="0.472637 0.580381 0.109316"/>
                <!-- Density 20 kg/m^3 -->
                <joint name="slide" type="slide" pos="-0.5 0 0" axis="1 0 0" range="0.0 0.8" limited="true" 
                  damping="1" frictionloss="0"
                  />
                <geom fromto="0 -0.048 0.5 0 0.048 0.5" size="0.25" type="cylinder" material="MatDark"
                  contype="0" conaffinity="0"  group="1"
                  />
                <geom fromto="0 -0.05 0.5 0 0.05 0.5" size="0.2" type="cylinder" material="MatGlass"
                  contype="0" conaffinity="0"  group="1" 
                />
                <geom size="0.45 0.04 0.73" type="box" friction="1 1 1" group="0" material="MatBright"/>
                <geom size="0.20 0.04 0.98" type="box" friction="1 1 1" group="0" material="MatBright"/>
                <geom fromto=" 0.2 -0.04  0.73  0.2  0.04  0.73" size="0.25" type="cylinder" friction="1 1 1" group="0" material="MatBright"/>
                <geom fromto=" 0.2 -0.04 -0.73  0.2  0.04 -0.73" size="0.25" type="cylinder" friction="1 1 1" group="0" material="MatBright"/>
                <geom fromto="-0.2 -0.04  0.73 -0.2  0.04  0.73" size="0.25" type="cylinder" friction="1 1 1" group="0" material="MatBright"/>
                <geom fromto="-0.2 -0.04 -0.73 -0.2  0.04 -0.73" size="0.25" type="cylinder" friction="1 1 1" group="0" material="MatBright"/>

                <body name="handle" pos="-0.4 0 -0.1">
                  <inertial pos="-0.017762 0 0" quat="0.365653 0.605347 -0.36522 0.605365" mass="0.1" diaginertia="0.0483771 0.0410001 0.0111013" />
                  <geom fromto="0 0.12  0.2 0 -0.12  0.2" size="0.015" type="cylinder" group="0" name="handle_up" material="MatDark"/>
                  <geom fromto="0 0.12 -0.2 0 -0.12 -0.2" size="0.015" type="cylinder" group="0" name="handle_bottom" material="MatDark"/>
                  <geom size="0.02 0.015 0.25" pos="0  0.135 0" type="box" group="0" name="front_handle" material="MatDark"/>
                  <geom size="0.02 0.015 0.25" pos="0 -0.135 0" type="box" group="0" name="back_handle" material="MatDark"/>
                  <!-- Don't render the door handle site by default -->
                  <site name="handle" pos="0.125 -0.10 0" size="0.02" rgba="0 0 1 0" />
                </body>
              </body>
            </body>
          </body>
        </body>
        <site name="bottom_site" pos="0 0 -0.6" rgba="0 0 0 0" size="0.005"/>
        <site name="top_site" pos="0 0 0.6" rgba="0 0 0 0" size="0.005"/>
        <site name="horizontal_radius_site" pos="0.3 0 0" rgba="0 0 0 0" size="0.1"/>
      </body>
    </worldbody>
</mujoco>